Workbook

Sheet Sheet1
A1: 日期 | B1: 倒计时 | C1: 超时 | D1: 预期剩余时间 | E1: 日均进度变化 | F1: 日均进度 | G1: 总进度 | H1: 阶段：难度+熟练 | I1: 阶段修正 | J1: 若维持最终完成度 | K1: 剩余目标日均进度 | L1: 每日进度（数理） | M1: 变动：教材掌握度 | N1: 持续：教材掌握度 | O1: 极限测试-总量 | P1: 极限测试-难题 | Q1: 难度因子 | R1: 极限测试-耗时(秒) | S1: 时间因子 | T1: 极限测试-正确 | U1: 精度因子 | V1: 极限测试-分步 | W1: 步骤因子 | X1: 极限测试-得分 | Y1: 总结 | Z1: 重点 | AA1: 恒温 | AB1: 歼灭 | AC1: 包围 | AD1: 自证 | AE1: 搬砖 | AF1: 计划 | AG1: 重开 | AH1: 兴趣 | AI1: 违心：确率变动 | AJ1: 违心：覆盖变动 | AK1: 违心：确率持续 | AL1: 违心：覆盖持续 | AM1: 违心：综合持续 | AN1: 当前状态 | AO1: 状态记录 | AP1: 睡眠 | AQ1: 锻炼 | AR1: 禁欲 | AS1: 晚休 | AT1: 午休 | AU1: 早上起床 | AV1: 中午休息 | AW1: 下午起床 | AX1: 晚上休息 | AY1: 锻炼记录 | AZ1: 禁欲记录
A2: 可用 | B2: 46015 | C2: NA | D2: NA | E2: NA | F2: NA | G2: NA | H2: 8 | I2: NA | J2: NA | K2: NA | L2: NA | M2: NA | N2: NA | O2: NA | P2: 1.5 | Q2: NA | R2: NA | S2: NA | T2: NA | U2: NA | V2: NA | W2: NA | X2: =IF(X$6<0,IF($I$7>=-(X$6),"OK","NG"),"OK") -> OK | Y2: =IF(Y$6<0,IF($I$7>=-(Y$6),"OK","NG"),"OK") -> OK | Z2: =IF(Z$6<0,IF($I$7>=-(Z$6),"OK","NG"),"OK") -> OK | AA2: =IF(AA$6<0,IF($I$7>=-(AA$6),"OK","NG"),"OK") -> OK | AB2: =IF(AB$6<0,IF($I$7>=-(AB$6),"OK","NG"),"OK") -> OK | AC2: =IF(AC$6<0,IF($I$7>=-(AC$6),"OK","NG"),"OK") -> OK | AD2: =IF(AD$6<0,IF($I$7>=-(AD$6),"OK","NG"),"OK") -> OK | AE2: =IF(AE$6<0,IF($I$7>=-(AE$6),"OK","NG"),"OK") -> OK | ... AH2: =IF(AH$6<0,IF($I$7>=-(AH$6),"OK","NG"),"OK") -> OK | AI2: NA | AJ2: NA | AK2: NA | AL2: NA | AM2: NA | AN2: NA | AO2: NA | AP2: NA | AQ2: NA | AR2: NA | AS2: NA | AT2: NA | AU2: NA | AV2: NA | AW2: NA | AX2: NA | AY2: NA | AZ2: NA
A3: 总计 | B3: NA | C3: NA | D3: NA | E3: NA | F3: NA | G3: NA | H3: NA | I3: NA | J3: NA | K3: NA | L3: NA | M3: 0.75 | N3: NA | O3: NA | P3: NA | Q3: NA | R3: NA | S3: NA | T3: NA | U3: NA | V3: NA | W3: NA | X3: =Y3-100 -> 300 | Y3: =Z3-100 -> 400 | Z3: =AA3-100 -> 500 | AA3: =AB3-100 -> 600 | AB3: 700 | AC3: =AB3+100 -> 800 | AD3: =AC3+100 -> 900 | AE3: =AD3+100 -> 1000 | AF3: =AE3+100 -> 1100 | AG3: =AF3+100 -> 1200 | AH3: =AG3+100 -> 1300 | AI3: NA | AJ3: NA | AK3: NA | AL3: NA | AM3: NA | AN3: NA | AO3: NA | AP3: NA | AQ3: NA | AR3: NA | AS3: NA | AT3: NA | AU3: NA | AV3: NA | AW3: NA | AX3: NA | AY3: NA | AZ3: NA
A4: 权重 | B4: NA | C4: NA | D4: NA | E4: NA | F4: NA | G4: NA | H4: =1/H2 -> 0.125 | I4: NA | J4: NA | K4: 1 | L4: NA | M4: 0.5 | N4: NA | O4: NA | P4: 0.5 | Q4: NA | R4: NA | S4: NA | T4: NA | U4: NA | V4: 0.5 | W4: NA | X4: =Y4+$K4 -> 11 | Y4: =Z4+$K4 -> 10 | Z4: =AA4+$K4 -> 9 | AA4: =AB4+$K4 -> 8 | AB4: =AC4+$K4 -> 7 | AC4: =AD4+$K4 -> 6 | AD4: =AE4+$K4 -> 5 | AE4: =AF4+$K4 -> 4 | ... AG4: =AH4+$K4 -> 2 | AH4: 1 | AI4: NA | AJ4: NA | AK4: NA | AL4: NA | AM4: 0.25 | AN4: NA | AO4: NA | AP4: NA | AQ4: NA | AR4: NA | AS4: NA | AT4: NA | AU4: NA | AV4: NA | AW4: NA | AX4: NA | AY4: NA | AZ4: NA
A5: 归一化 | B5: NA | C5: NA | D5: NA | E5: NA | F5: NA | G5: NA | H5: NA | I5: NA | J5: NA | K5: NA | L5: NA | M5: NA | N5: NA | O5: NA | P5: NA | Q5: NA | R5: 120 | S5: NA | T5: NA | U5: NA | V5: NA | W5: NA | X5: =(X4/SUM($X$4:$AH$4)) -> 0.16666667 | Y5: =(Y4/SUM($X$4:$AH$4)) -> 0.15151515 | Z5: =(Z4/SUM($X$4:$AH$4)) -> 0.13636364 | AA5: =(AA4/SUM($X$4:$AH$4)) -> 0.12121212 | AB5: =(AB4/SUM($X$4:$AH$4)) -> 0.10606061 | AC5: =(AC4/SUM($X$4:$AH$4)) -> 0.090909091 | AD5: =(AD4/SUM($X$4:$AH$4)) -> 0.075757576 | AE5: =(AE4/SUM($X$4:$AH$4)) -> 0.060606061 | ... AH5: =(AH4/SUM($X$4:$AH$4)) -> 0.015151515 | AI5: NA | AJ5: NA | AK5: NA | AL5: NA | AM5: NA | AN5: NA | AO5: NA | AP5: NA | AQ5: 200 | AR5: NA | AS5: 0.33333333 | AT5: 0.041666667 | AU5: NA | AV5: NA | AW5: NA | AX5: NA | AY5: NA | AZ5: NA
A6: 每次 | B6: NA | C6: NA | D6: NA | E6: NA | F6: NA | G6: NA | H6: NA | I6: NA | J6: NA | K6: NA | L6: NA | M6: NA | N6: NA | O6: NA | P6: NA | Q6: NA | R6: NA | S6: NA | T6: NA | U6: NA | V6: NA | W6: NA | X6: =X5/X3 -> 0.00055555556 | Y6: =Y5/Y3 -> 0.00037878788 | Z6: =Z5/Z3 -> 0.00027272727 | AA6: =AA5/AA3 -> 0.0002020202 | AB6: =AB5/AB3 -> 0.00015151515 | AC6: =AC5/AC3 -> 0.00011363636 | AD6: =AD5/AD3 -> 8.4175084e-05 | AE6: =AE5/AE3 -> 6.0606061e-05 | ... AH6: =AH5/AH3 -> 1.1655012e-05 | AI6: NA | AJ6: NA | AK6: NA | AL6: NA | AM6: NA | AN6: NA | AO6: NA | AP6: NA | AQ6: NA | AR6: NA | AS6: NA | AT6: NA | AU6: NA | AV6: NA | AW6: NA | AX6: NA | AY6: NA | AZ6: NA
A7: 累积 | B7: NA | C7: NA | D7: NA | E7: NA | F7: NA | G7: =MAX(G8:G690) -> 1.0330572 | H7: 0 | I7: =SUM(I8:I809) -> 3.5079624 | J7: NA | K7: NA | L7: =SUM(L8:L809) -> 2.9112225 | M7: NA | N7: =MAX(N8:N809) -> 1 | O7: NA | P7: NA | Q7: NA | R7: NA | S7: NA | T7: NA | U7: NA | V7: NA | W7: NA | X7: =SUM(X8:X809) -> 606.51019 | Y7: =SUM(Y8:Y809) -> 2506.79 | Z7: =SUM(Z8:Z809) -> 2957 | AA7: =SUM(AA8:AA809) -> 2662 | AB7: =SUM(AB8:AB809) -> 1133 | AC7: =SUM(AC8:AC809) -> 509.65 | AD7: =SUM(AD8:AD809) -> 599 | AE7: =SUM(AE8:AE809) -> 0 | ... AH7: =SUM(AH8:AH809) -> 14 | AI7: NA | AJ7: NA | AK7: NA | AL7: NA | AM7: NA | AN7: NA | AO7: NA | AP7: NA | AQ7: NA | AR7: NA | AS7: NA | AT7: NA | AU7: NA | AV7: NA | AW7: NA | AX7: NA | AY7: NA | AZ7: NA
A8: 45333 | B8: =B$2-A8+1 -> 683 | C8: =D8-B8 -> 4899 | D8: =IF(F8>0,ROUND(((1-G8)/F8),0),FACT(128)) -> 5582 | E8: =F8 -> 0.00017911119 | F8: =G8/(ROW()-7) -> 0.00017911119 | G8: =(SUM($I$8:$I8)*(MAX(M$3-M$4,0))+(N8*MAX(M$4,0)))*(1-$AM$4)+(AM8*$AM$4) -> 0.00017911119 | H8: =0.5+(MONTH(A8)+(YEAR(A8)-2024)*12)/((YEAR(B$2)-2023)*12) -> 0.58333333 | I8: =L8*H8 -> 0.00095525967 | J8: =F8*B8+G8 -> 0.12251205 | K8: =((1-G8)/B8)-F8 -> 0.0012847554 | L8: =Y8*Y$6+X8*X$6+Z8*Z$6+AA8*AA$6+AB8*AB$6+AC8*AC$6+AD8*AD$6+AE8*AE$6+AF8*AF$6+AG8*AG$6+AH8*AH$6 -> 0.001637588 | M8: 0 | N8: =M8 -> 0 | O8: 0 | P8: 0 | Q8: =($P$2-$P$4)+((P8/(MAX(1/FACT(128),O8)))*$P$4) -> 1 | R8: 0 | S8: =O8*$R$5/MAX(1/FACT(128),R8) -> 0 | T8: 0 | U8: =MAX(1,T8)/(MAX(1,O8)) -> 1 | V8: 0 | W8: =($V$4*V8/(MAX(1,O8)))+1 -> 1 | X8: =O8*Q8*S8*U8*W8 -> 0 | Y8: 0 | Z8: 0 | AA8: 0 | AB8: 0 | AC8: 0 | AD8: 17 | AE8: 0 | AF8: 5 | AG8: 0 | AH8: 0 | AI8: 0 | AJ8: 0 | AK8: =AI8 -> 0 | AL8: =AJ8 -> 0 | AM8: =AL8*AK8 -> 0 | AN8: =IFERROR(AVERAGEIF(AO$8:AO$8,">0",AO$8:AO$8),0) -> 0 | AO8: =AP8*0.75+AQ8*0.125+AR8*0.125 -> 0 | AP8: =AVERAGE(AS8:AT8) -> 0 | AQ8: =AY8/AQ$5 -> 0 | AR8: =IF(AZ8>=0,1/(AZ8+1),0) -> 0 | AS8: =("24:00"-AX8+AU8)/$AS$5 -> 0 | AT8: =(AW8-AV8)/$AT$5 -> 0 | AU8: 0 | AV8: 0 | AW8: 0 | AX8: 1 | AY8: 0 | AZ8: -1
A9: 45334 | B9: =B$2-A9+1 -> 682 | C9: =D9-B9 -> 4787 | D9: =IF(F9>0,ROUND(((1-G9)/F9),0),FACT(128)) -> 5469 | E9: =F9-F8 -> 3.6617357e-06 | F9: =G9/(ROW()-7) -> 0.00018277292 | G9: =(SUM($I$8:$I9)*(MAX(M$3-M$4,0))+(N9*MAX(M$4,0)))*(1-$AM$4)+(AM9*$AM$4) -> 0.00036554585 | H9: =0.5+(MONTH(A9)+(YEAR(A9)-2024)*12)/((YEAR(B$2)-2023)*12) -> 0.58333333 | I9: =L9*H9 -> 0.00099431818 | J9: =F9*B9+G9 -> 0.12501668 | K9: =((1-G9)/B9)-F9 -> 0.0012829667 | L9: =Y9*Y$6+X9*X$6+Z9*Z$6+AA9*AA$6+AB9*AB$6+AC9*AC$6+AD9*AD$6+AE9*AE$6+AF9*AF$6+AG9*AG$6+AH9*AH$6 -> 0.0017045455 | M9: 0 | N9: =IF(M9>N8,M9,N8) -> 0 | O9: 0 | P9: 0 | Q9: =($P$2-$P$4)+((P9/(MAX(1/FACT(128),O9)))*$P$4) -> 1 | R9: 0 | S9: =O9*$R$5/MAX(1/FACT(128),R9) -> 0 | T9: 0 | U9: =MAX(1,T9)/(MAX(1,O9)) -> 1 | V9: 0 | W9: =($V$4*V9/(MAX(1,O9)))+1 -> 1 | X9: =O9*Q9*S9*U9*W9 -> 0 | Y9: 0 | Z9: 0 | AA9: 2 | AB9: 0 | AC9: 7 | AD9: 6 | AE9: 0 | AF9: 0 | AG9: 0 | AH9: 0 | AI9: 0 | AJ9: 0 | AK9: =IF(AI9>0,AI9,AK8) -> 0 | AL9: =IF(AJ9>0,AJ9,AL8) -> 0 | AM9: =AL9*AK9 -> 0 | AN9: =IFERROR(AVERAGEIF(AO$8:AO8,">0",AO$8:AO8),0) -> 0 | AO9: =AP9*0.75+AQ9*0.125+AR9*0.125 -> 0 | AP9: =AVERAGE(AS9:AT9) -> 0 | AQ9: =AY9/AQ$5 -> 0 | AR9: =IF(AZ9>=0,1/(AZ9+1),0) -> 0 | AS9: =IF((("24:00"-AX9+AU9)/$AS$5)>0,(("24:00"-AX9+AU9)/$AS$5),AS8) -> 0 | AT9: =IF(((AW9-AV9)/$AT$5)>0,((AW9-AV9)/$AT$5),AT8) -> 0 | AU9: 0 | AV9: 0 | AW9: 0 | AX9: 1 | AY9: 0 | AZ9: -1
A10: 45335 | B10: =B$2-A10+1 -> 681 | C10: =D10-B10 -> 4644 | D10: =IF(F10>0,ROUND(((1-G10)/F10),0),FACT(128)) -> 5325 | E10: =F10-F9 -> 4.9032385e-06 | F10: =G10/(ROW()-7) -> 0.00018767616 | G10: =(SUM($I$8:$I10)*(MAX(M$3-M$4,0))+(N10*MAX(M$4,0)))*(1-$AM$4)+(AM10*$AM$4) -> 0.00056302849 | H10: =0.5+(MONTH(A10)+(YEAR(A10)-2024)*12)/((YEAR(B$2)-2023)*12) -> 0.58333333 | I10: =L10*H10 -> 0.0010532407 | J10: =F10*B10+G10 -> 0.12837049 | K10: =((1-G10)/B10)-F10 -> 0.0012799259 | L10: =Y10*Y$6+X10*X$6+Z10*Z$6+AA10*AA$6+AB10*AB$6+AC10*AC$6+AD10*AD$6+AE10*AE$6+AF10*AF$6+AG10*AG$6+AH10*AH$6 -> 0.0018055556 | M10: 0 | N10: =IF(M10>N9,M10,N9) -> 0 | O10: 0 | P10: 0 | Q10: =($P$2-$P$4)+((P10/(MAX(1/FACT(128),O10)))*$P$4) -> 1 | R10: 0 | S10: =O10*$R$5/MAX(1/FACT(128),R10) -> 0 | T10: 0 | U10: =MAX(1,T10)/(MAX(1,O10)) -> 1 | V10: 0 | W10: =($V$4*V10/(MAX(1,O10)))+1 -> 1 | X10: =O10*Q10*S10*U10*W10 -> 0 | Y10: 0 | Z10: 0 | AA10: 2 | AB10: 0 | AC10: 5 | AD10: 9 | AE10: 0 | AF10: 0 | AG10: 3 | AH10: 0 | AI10: 0 | AJ10: 0 | AK10: =IF(AI10>0,AI10,AK9) -> 0 | AL10: =IF(AJ10>0,AJ10,AL9) -> 0 | AM10: =AL10*AK10 -> 0 | AN10: =IFERROR(AVERAGEIF(AO$8:AO9,">0",AO$8:AO9),0) -> 0 | AO10: =AP10*0.75+AQ10*0.125+AR10*0.125 -> 0 | AP10: =AVERAGE(AS10:AT10) -> 0 | AQ10: =AY10/AQ$5 -> 0 | AR10: =IF(AZ10>=0,1/(AZ10+1),0) -> 0 | AS10: =IF((("24:00"-AX10+AU10)/$AS$5)>0,(("24:00"-AX10+AU10)/$AS$5),AS9) -> 0 | AT10: =IF(((AW10-AV10)/$AT$5)>0,((AW10-AV10)/$AT$5),AT9) -> 0 | AU10: 0 | AV10: 0 | AW10: 0 | AX10: 1 | AY10: 0 | AZ10: -1
A11: 45336 | B11: =B$2-A11+1 -> 680 | C11: =D11-B11 -> 4636 | D11: =IF(F11>0,ROUND(((1-G11)/F11),0),FACT(128)) -> 5316 | E11: =F11-F10 -> 3.1107317e-07 | F11: =G11/(ROW()-7) -> 0.00018798724 | G11: =(SUM($I$8:$I11)*(MAX(M$3-M$4,0))+(N11*MAX(M$4,0)))*(1-$AM$4)+(AM11*$AM$4) -> 0.00075194894 | H11: =0.5+(MONTH(A11)+(YEAR(A11)-2024)*12)/((YEAR(B$2)-2023)*12) -> 0.58333333 | I11: =L11*H11 -> 0.0010075758 | J11: =F11*B11+G11 -> 0.12858327 | K11: =((1-G11)/B11)-F11 -> 0.0012814952 | L11: =Y11*Y$6+X11*X$6+Z11*Z$6+AA11*AA$6+AB11*AB$6+AC11*AC$6+AD11*AD$6+AE11*AE$6+AF11*AF$6+AG11*AG$6+AH11*AH$6 -> 0.0017272727 | M11: 0 | N11: =IF(M11>N10,M11,N10) -> 0 | O11: 0 | P11: 0 | Q11: =($P$2-$P$4)+((P11/(MAX(1/FACT(128),O11)))*$P$4) -> 1 | R11: 0 | S11: =O11*$R$5/MAX(1/FACT(128),R11) -> 0 | T11: 0 | U11: =MAX(1,T11)/(MAX(1,O11)) -> 1 | V11: 0 | W11: =($V$4*V11/(MAX(1,O11)))+1 -> 1 | X11: =O11*Q11*S11*U11*W11 -> 0 | Y11: 0 | Z11: 3 | AA11: 0 | AB11: 0 | AC11: 8 | AD11: 0 | AE11: 0 | AF11: 0 | AG11: 0 | AH11: 0 | AI11: 0 | AJ11: 0 | AK11: =IF(AI11>0,AI11,AK10) -> 0 | AL11: =IF(AJ11>0,AJ11,AL10) -> 0 | AM11: =AL11*AK11 -> 0 | AN11: =IFERROR(AVERAGEIF(AO$8:AO10,">0",AO$8:AO10),0) -> 0 | AO11: =AP11*0.75+AQ11*0.125+AR11*0.125 -> 0 | AP11: =AVERAGE(AS11:AT11) -> 0 | AQ11: =AY11/AQ$5 -> 0 | AR11: =IF(AZ11>=0,1/(AZ11+1),0) -> 0 | AS11: =IF((("24:00"-AX11+AU11)/$AS$5)>0,(("24:00"-AX11+AU11)/$AS$5),AS10) -> 0 | AT11: =IF(((AW11-AV11)/$AT$5)>0,((AW11-AV11)/$AT$5),AT10) -> 0 | AU11: 0 | AV11: 0 | AW11: 0 | AX11: 1 | AY11: 0 | AZ11: -1
A12: 45337 | B12: =B$2-A12+1 -> 679 | C12: =D12-B12 -> 4599 | D12: =IF(F12>0,ROUND(((1-G12)/F12),0),FACT(128)) -> 5278 | E12: =F12-F11 -> 1.2914419e-06 | F12: =G12/(ROW()-7) -> 0.00018927868 | G12: =(SUM($I$8:$I12)*(MAX(M$3-M$4,0))+(N12*MAX(M$4,0)))*(1-$AM$4)+(AM12*$AM$4) -> 0.00094639338 | H12: =0.5+(MONTH(A12)+(YEAR(A12)-2024)*12)/((YEAR(B$2)-2023)*12) -> 0.58333333 | I12: =L12*H12 -> 0.001037037 | J12: =F12*B12+G12 -> 0.12946662 | K12: =((1-G12)/B12)-F12 -> 0.0012820816 | L12: =Y12*Y$6+X12*X$6+Z12*Z$6+AA12*AA$6+AB12*AB$6+AC12*AC$6+AD12*AD$6+AE12*AE$6+AF12*AF$6+AG12*AG$6+AH12*AH$6 -> 0.0017777778 | M12: 0 | N12: =IF(M12>N11,M12,N11) -> 0 | O12: 0 | P12: 0 | Q12: =($P$2-$P$4)+((P12/(MAX(1/FACT(128),O12)))*$P$4) -> 1 | R12: 0 | S12: =O12*$R$5/MAX(1/FACT(128),R12) -> 0 | T12: 0 | U12: =MAX(1,T12)/(MAX(1,O12)) -> 1 | V12: 0 | W12: =($V$4*V12/(MAX(1,O12)))+1 -> 1 | X12: =O12*Q12*S12*U12*W12 -> 0 | Y12: 0 | Z12: 3 | AA12: 0 | AB12: 0 | AC12: 8 | AD12: 0 | AE12: 0 | AF12: 0 | AG12: 2 | AH12: 0 | AI12: 0 | AJ12: 0 | AK12: =IF(AI12>0,AI12,AK11) -> 0 | AL12: =IF(AJ12>0,AJ12,AL11) -> 0 | AM12: =AL12*AK12 -> 0 | AN12: =IFERROR(AVERAGEIF(AO$8:AO11,">0",AO$8:AO11),0) -> 0 | AO12: =AP12*0.75+AQ12*0.125+AR12*0.125 -> 0 | AP12: =AVERAGE(AS12:AT12) -> 0 | AQ12: =AY12/AQ$5 -> 0 | AR12: =IF(AZ12>=0,1/(AZ12+1),0) -> 0 | AS12: =IF((("24:00"-AX12+AU12)/$AS$5)>0,(("24:00"-AX12+AU12)/$AS$5),AS11) -> 0 | AT12: =IF(((AW12-AV12)/$AT$5)>0,((AW12-AV12)/$AT$5),AT11) -> 0 | AU12: 0 | AV12: 0 | AW12: 0 | AX12: 1 | AY12: 0 | AZ12: -1
A13: 45338 | B13: =B$2-A13+1 -> 678 | C13: =D13-B13 -> 4511 | D13: =IF(F13>0,ROUND(((1-G13)/F13),0),FACT(128)) -> 5189 | E13: =F13-F12 -> 3.208657e-06 | F13: =G13/(ROW()-7) -> 0.00019248733 | G13: =(SUM($I$8:$I13)*(MAX(M$3-M$4,0))+(N13*MAX(M$4,0)))*(1-$AM$4)+(AM13*$AM$4) -> 0.001154924 | H13: =0.5+(MONTH(A13)+(YEAR(A13)-2024)*12)/((YEAR(B$2)-2023)*12) -> 0.58333333 | I13: =L13*H13 -> 0.0011121633 | J13: =F13*B13+G13 -> 0.13166134 | K13: =((1-G13)/B13)-F13 -> 0.0012807355 | L13: =Y13*Y$6+X13*X$6+Z13*Z$6+AA13*AA$6+AB13*AB$6+AC13*AC$6+AD13*AD$6+AE13*AE$6+AF13*AF$6+AG13*AG$6+AH13*AH$6 -> 0.0019065657 | M13: 0 | N13: =IF(M13>N12,M13,N12) -> 0 | O13: 0 | P13: 0 | Q13: =($P$2-$P$4)+((P13/(MAX(1/FACT(128),O13)))*$P$4) -> 1 | R13: 0 | S13: =O13*$R$5/MAX(1/FACT(128),R13) -> 0 | T13: 0 | U13: =MAX(1,T13)/(MAX(1,O13)) -> 1 | V13: 0 | W13: =($V$4*V13/(MAX(1,O13)))+1 -> 1 | X13: =O13*Q13*S13*U13*W13 -> 0 | Y13: 0 | Z13: 5 | AA13: 1 | AB13: 0 | AC13: 3 | AD13: 0 | AE13: 0 | AF13: 0 | AG13: 0 | AH13: 0 | AI13: 0 | AJ13: 0 | AK13: =IF(AI13>0,AI13,AK12) -> 0 | AL13: =IF(AJ13>0,AJ13,AL12) -> 0 | AM13: =AL13*AK13 -> 0 | AN13: =IFERROR(AVERAGEIF(AO$8:AO12,">0",AO$8:AO12),0) -> 0 | AO13: =AP13*0.75+AQ13*0.125+AR13*0.125 -> 0 | AP13: =AVERAGE(AS13:AT13) -> 0 | AQ13: =AY13/AQ$5 -> 0 | AR13: =IF(AZ13>=0,1/(AZ13+1),0) -> 0 | AS13: =IF((("24:00"-AX13+AU13)/$AS$5)>0,(("24:00"-AX13+AU13)/$AS$5),AS12) -> 0 | AT13: =IF(((AW13-AV13)/$AT$5)>0,((AW13-AV13)/$AT$5),AT12) -> 0 | AU13: 0 | AV13: 0 | AW13: 0 | AX13: 1 | AY13: 0 | AZ13: -1
A14: 45339 | B14: =B$2-A14+1 -> 677 | C14: =D14-B14 -> 4466 | D14: =IF(F14>0,ROUND(((1-G14)/F14),0),FACT(128)) -> 5143 | E14: =F14-F13 -> 1.7000418e-06 | F14: =G14/(ROW()-7) -> 0.00019418738 | G14: =(SUM($I$8:$I14)*(MAX(M$3-M$4,0))+(N14*MAX(M$4,0)))*(1-$AM$4)+(AM14*$AM$4) -> 0.0013593116 | H14: =0.5+(MONTH(A14)+(YEAR(A14)-2024)*12)/((YEAR(B$2)-2023)*12) -> 0.58333333 | I14: =L14*H14 -> 0.0010900673 | J14: =F14*B14+G14 -> 0.13282416 | K14: =((1-G14)/B14)-F14 -> 0.0012809097 | L14: =Y14*Y$6+X14*X$6+Z14*Z$6+AA14*AA$6+AB14*AB$6+AC14*AC$6+AD14*AD$6+AE14*AE$6+AF14*AF$6+AG14*AG$6+AH14*AH$6 -> 0.0018686869 | M14: 0 | N14: =IF(M14>N13,M14,N13) -> 0 | O14: 0 | P14: 0 | Q14: =($P$2-$P$4)+((P14/(MAX(1/FACT(128),O14)))*$P$4) -> 1 | R14: 0 | S14: =O14*$R$5/MAX(1/FACT(128),R14) -> 0 | T14: 0 | U14: =MAX(1,T14)/(MAX(1,O14)) -> 1 | V14: 0 | W14: =($V$4*V14/(MAX(1,O14)))+1 -> 1 | X14: =O14*Q14*S14*U14*W14 -> 0 | Y14: 0 | Z14: 5 | AA14: 0 | AB14: 0 | AC14: 0 | AD14: 6 | AE14: 0 | AF14: 0 | AG14: 0 | AH14: 0 | AI14: 0 | AJ14: 0 | AK14: =IF(AI14>0,AI14,AK13) -> 0 | AL14: =IF(AJ14>0,AJ14,AL13) -> 0 | AM14: =AL14*AK14 -> 0 | AN14: =IFERROR(AVERAGEIF(AO$8:AO13,">0",AO$8:AO13),0) -> 0 | AO14: =AP14*0.75+AQ14*0.125+AR14*0.125 -> 0 | AP14: =AVERAGE(AS14:AT14) -> 0 | AQ14: =AY14/AQ$5 -> 0 | AR14: =IF(AZ14>=0,1/(AZ14+1),0) -> 0 | AS14: =IF((("24:00"-AX14+AU14)/$AS$5)>0,(("24:00"-AX14+AU14)/$AS$5),AS13) -> 0 | AT14: =IF(((AW14-AV14)/$AT$5)>0,((AW14-AV14)/$AT$5),AT13) -> 0 | AU14: 0 | AV14: 0 | AW14: 0 | AX14: 1 | AY14: 0 | AZ14: -1
A15: 45340 | B15: =B$2-A15+1 -> 676 | C15: =D15-B15 -> 4381 | D15: =IF(F15>0,ROUND(((1-G15)/F15),0),FACT(128)) -> 5057 | E15: =F15-F14 -> 3.2314444e-06 | F15: =G15/(ROW()-7) -> 0.00019741882 | G15: =(SUM($I$8:$I15)*(MAX(M$3-M$4,0))+(N15*MAX(M$4,0)))*(1-$AM$4)+(AM15*$AM$4) -> 0.0015793506 | H15: =0.5+(MONTH(A15)+(YEAR(A15)-2024)*12)/((YEAR(B$2)-2023)*12) -> 0.58333333 | I15: =L15*H15 -> 0.001173541 | J15: =F15*B15+G15 -> 0.13503447 | K15: =((1-G15)/B15)-F15 -> 0.0012795348 | L15: =Y15*Y$6+X15*X$6+Z15*Z$6+AA15*AA$6+AB15*AB$6+AC15*AC$6+AD15*AD$6+AE15*AE$6+AF15*AF$6+AG15*AG$6+AH15*AH$6 -> 0.0020117845 | M15: 0 | N15: =IF(M15>N14,M15,N14) -> 0 | O15: 0 | P15: 0 | Q15: =($P$2-$P$4)+((P15/(MAX(1/FACT(128),O15)))*$P$4) -> 1 | R15: 0 | S15: =O15*$R$5/MAX(1/FACT(128),R15) -> 0 | T15: 0 | U15: =MAX(1,T15)/(MAX(1,O15)) -> 1 | V15: 0 | W15: =($V$4*V15/(MAX(1,O15)))+1 -> 1 | X15: =O15*Q15*S15*U15*W15 -> 0 | Y15: 0 | Z15: 5 | AA15: 0 | AB15: 0 | AC15: 2 | AD15: 5 | AE15: 0 | AF15: 0 | AG15: 0 | AH15: 0 | AI15: 0 | AJ15: 0 | AK15: =IF(AI15>0,AI15,AK14) -> 0 | AL15: =IF(AJ15>0,AJ15,AL14) -> 0 | AM15: =AL15*AK15 -> 0 | AN15: =IFERROR(AVERAGEIF(AO8:AO14,">0",AO8:AO14),0) -> 0 | AO15: =AP15*0.75+AQ15*0.125+AR15*0.125 -> 0 | AP15: =AVERAGE(AS15:AT15) -> 0 | AQ15: =AY15/AQ$5 -> 0 | AR15: =IF(AZ15>=0,1/(AZ15+1),0) -> 0 | AS15: =IF((("24:00"-AX15+AU15)/$AS$5)>0,(("24:00"-AX15+AU15)/$AS$5),AS14) -> 0 | AT15: =IF(((AW15-AV15)/$AT$5)>0,((AW15-AV15)/$AT$5),AT14) -> 0 | AU15: 0 | AV15: 0 | AW15: 0 | AX15: 1 | AY15: 0 | AZ15: -1
A16: 45341 | B16: =B$2-A16+1 -> 675 | C16: =D16-B16 -> 4383 | D16: =IF(F16>0,ROUND(((1-G16)/F16),0),FACT(128)) -> 5058 | E16: =F16-F15 -> -4.4057074e-08 | F16: =G16/(ROW()-7) -> 0.00019737476 | G16: =(SUM($I$8:$I16)*(MAX(M$3-M$4,0))+(N16*MAX(M$4,0)))*(1-$AM$4)+(AM16*$AM$4) -> 0.0017763729 | H16: =0.5+(MONTH(A16)+(YEAR(A16)-2024)*12)/((YEAR(B$2)-2023)*12) -> 0.58333333 | I16: =L16*H16 -> 0.0010507856 | J16: =F16*B16+G16 -> 0.13500434 | K16: =((1-G16)/B16)-F16 -> 0.0012814751 | L16: =Y16*Y$6+X16*X$6+Z16*Z$6+AA16*AA$6+AB16*AB$6+AC16*AC$6+AD16*AD$6+AE16*AE$6+AF16*AF$6+AG16*AG$6+AH16*AH$6 -> 0.0018013468 | M16: 0 | N16: =IF(M16>N15,M16,N15) -> 0 | O16: 0 | P16: 0 | Q16: =($P$2-$P$4)+((P16/(MAX(1/FACT(128),O16)))*$P$4) -> 1 | R16: 0 | S16: =O16*$R$5/MAX(1/FACT(128),R16) -> 0 | T16: 0 | U16: =MAX(1,T16)/(MAX(1,O16)) -> 1 | V16: 0 | W16: =($V$4*V16/(MAX(1,O16)))+1 -> 1 | X16: =O16*Q16*S16*U16*W16 -> 0 | Y16: 0 | Z16: 0 | AA16: 6 | AB16: 0 | AC16: 0 | AD16: 7 | AE16: 0 | AF16: 0 | AG16: 0 | AH16: 0 | AI16: 0 | AJ16: 0 | AK16: =IF(AI16>0,AI16,AK15) -> 0 | AL16: =IF(AJ16>0,AJ16,AL15) -> 0 | AM16: =AL16*AK16 -> 0 | AN16: =IFERROR(AVERAGEIF(AO9:AO15,">0",AO9:AO15),0) -> 0 | AO16: =AP16*0.75+AQ16*0.125+AR16*0.125 -> 0 | AP16: =AVERAGE(AS16:AT16) -> 0 | AQ16: =AY16/AQ$5 -> 0 | AR16: =IF(AZ16>=0,1/(AZ16+1),0) -> 0 | AS16: =IF((("24:00"-AX16+AU16)/$AS$5)>0,(("24:00"-AX16+AU16)/$AS$5),AS15) -> 0 | AT16: =IF(((AW16-AV16)/$AT$5)>0,((AW16-AV16)/$AT$5),AT15) -> 0 | AU16: 0 | AV16: 0 | AW16: 0 | AX16: 1 | AY16: 0 | AZ16: -1
A17: 45342 | B17: =B$2-A17+1 -> 674 | C17: =D17-B17 -> 4393 | D17: =IF(F17>0,ROUND(((1-G17)/F17),0),FACT(128)) -> 5067 | E17: =F17-F16 -> -4.0351165e-07 | F17: =G17/(ROW()-7) -> 0.00019697125 | G17: =(SUM($I$8:$I17)*(MAX(M$3-M$4,0))+(N17*MAX(M$4,0)))*(1-$AM$4)+(AM17*$AM$4) -> 0.0019697125 | H17: =0.5+(MONTH(A17)+(YEAR(A17)-2024)*12)/((YEAR(B$2)-2023)*12) -> 0.58333333 | I17: =L17*H17 -> 0.0010311448 | J17: =F17*B17+G17 -> 0.13472834 | K17: =((1-G17)/B17)-F17 -> 0.0012837859 | L17: =Y17*Y$6+X17*X$6+Z17*Z$6+AA17*AA$6+AB17*AB$6+AC17*AC$6+AD17*AD$6+AE17*AE$6+AF17*AF$6+AG17*AG$6+AH17*AH$6 -> 0.0017676768 | M17: 0 | N17: =IF(M17>N16,M17,N16) -> 0 | O17: 0 | P17: 0 | Q17: =($P$2-$P$4)+((P17/(MAX(1/FACT(128),O17)))*$P$4) -> 1 | R17: 0 | S17: =O17*$R$5/MAX(1/FACT(128),R17) -> 0 | T17: 0 | U17: =MAX(1,T17)/(MAX(1,O17)) -> 1 | V17: 0 | W17: =($V$4*V17/(MAX(1,O17)))+1 -> 1 | X17: =O17*Q17*S17*U17*W17 -> 0 | Y17: 0 | Z17: 0 | AA17: 8 | AB17: 1 | AC17: 0 | AD17: 0 | AE17: 0 | AF17: 0 | AG17: 0 | AH17: 0 | AI17: 0 | AJ17: 0 | AK17: =IF(AI17>0,AI17,AK16) -> 0 | AL17: =IF(AJ17>0,AJ17,AL16) -> 0 | AM17: =AL17*AK17 -> 0 | AN17: =IFERROR(AVERAGEIF(AO10:AO16,">0",AO10:AO16),0) -> 0 | AO17: =AP17*0.75+AQ17*0.125+AR17*0.125 -> 0 | AP17: =AVERAGE(AS17:AT17) -> 0 | AQ17: =AY17/AQ$5 -> 0 | AR17: =IF(AZ17>=0,1/(AZ17+1),0) -> 0 | AS17: =IF((("24:00"-AX17+AU17)/$AS$5)>0,(("24:00"-AX17+AU17)/$AS$5),AS16) -> 0 | AT17: =IF(((AW17-AV17)/$AT$5)>0,((AW17-AV17)/$AT$5),AT16) -> 0 | AU17: 0 | AV17: 0 | AW17: 0 | AX17: 1 | AY17: 0 | AZ17: -1
A18: 45343 | B18: =B$2-A18+1 -> 673 | C18: =D18-B18 -> 4076 | D18: =IF(F18>0,ROUND(((1-G18)/F18),0),FACT(128)) -> 4749 | E18: =F18-F17 -> 1.3103193e-05 | F18: =G18/(ROW()-7) -> 0.00021007444 | G18: =(SUM($I$8:$I18)*(MAX(M$3-M$4,0))+(N18*MAX(M$4,0)))*(1-$AM$4)+(AM18*$AM$4) -> 0.0023108189 | H18: =0.5+(MONTH(A18)+(YEAR(A18)-2024)*12)/((YEAR(B$2)-2023)*12) -> 0.58333333 | I18: =L18*H18 -> 0.001819234 | J18: =F18*B18+G18 -> 0.14369092 | K18: =((1-G18)/B18)-F18 -> 0.001272376 | L18: =Y18*Y$6+X18*X$6+Z18*Z$6+AA18*AA$6+AB18*AB$6+AC18*AC$6+AD18*AD$6+AE18*AE$6+AF18*AF$6+AG18*AG$6+AH18*AH$6 -> 0.0031186869 | M18: 0 | N18: =IF(M18>N17,M18,N17) -> 0 | O18: 0 | P18: 0 | Q18: =($P$2-$P$4)+((P18/(MAX(1/FACT(128),O18)))*$P$4) -> 1 | R18: 0 | S18: =O18*$R$5/MAX(1/FACT(128),R18) -> 0 | T18: 0 | U18: =MAX(1,T18)/(MAX(1,O18)) -> 1 | V18: 0 | W18: =($V$4*V18/(MAX(1,O18)))+1 -> 1 | X18: =O18*Q18*S18*U18*W18 -> 0 | Y18: 0 | Z18: 0 | AA18: 2 | AB18: 0 | AC18: 15 | AD18: 12 | AE18: 0 | AF18: 0 | AG18: 0 | AH18: 0 | AI18: 0 | AJ18: 0 | AK18: =IF(AI18>0,AI18,AK17) -> 0 | AL18: =IF(AJ18>0,AJ18,AL17) -> 0 | AM18: =AL18*AK18 -> 0 | AN18: =IFERROR(AVERAGEIF(AO11:AO17,">0",AO11:AO17),0) -> 0 | AO18: =AP18*0.75+AQ18*0.125+AR18*0.125 -> 0 | AP18: =AVERAGE(AS18:AT18) -> 0 | AQ18: =AY18/AQ$5 -> 0 | AR18: =IF(AZ18>=0,1/(AZ18+1),0) -> 0 | AS18: =IF((("24:00"-AX18+AU18)/$AS$5)>0,(("24:00"-AX18+AU18)/$AS$5),AS17) -> 0 | AT18: =IF(((AW18-AV18)/$AT$5)>0,((AW18-AV18)/$AT$5),AT17) -> 0 | AU18: 0 | AV18: 0 | AW18: 0 | AX18: 1 | AY18: 0 | AZ18: -1
A19: 45344 | B19: =B$2-A19+1 -> 672 | C19: =D19-B19 -> 4080 | D19: =IF(F19>0,ROUND(((1-G19)/F19),0),FACT(128)) -> 4752 | E19: =F19-F18 -> -1.6701319e-07 | F19: =G19/(ROW()-7) -> 0.00020990743 | G19: =(SUM($I$8:$I19)*(MAX(M$3-M$4,0))+(N19*MAX(M$4,0)))*(1-$AM$4)+(AM19*$AM$4) -> 0.0025188892 | H19: =0.5+(MONTH(A19)+(YEAR(A19)-2024)*12)/((YEAR(B$2)-2023)*12) -> 0.58333333 | I19: =L19*H19 -> 0.0011097082 | J19: =F19*B19+G19 -> 0.14357668 | K19: =((1-G19)/B19)-F19 -> 0.0012744395 | L19: =Y19*Y$6+X19*X$6+Z19*Z$6+AA19*AA$6+AB19*AB$6+AC19*AC$6+AD19*AD$6+AE19*AE$6+AF19*AF$6+AG19*AG$6+AH19*AH$6 -> 0.0019023569 | M19: 0 | N19: =IF(M19>N18,M19,N18) -> 0 | O19: 0 | P19: 0 | Q19: =($P$2-$P$4)+((P19/(MAX(1/FACT(128),O19)))*$P$4) -> 1 | R19: 0 | S19: =O19*$R$5/MAX(1/FACT(128),R19) -> 0 | T19: 0 | U19: =MAX(1,T19)/(MAX(1,O19)) -> 1 | V19: 0 | W19: =($V$4*V19/(MAX(1,O19)))+1 -> 1 | X19: =O19*Q19*S19*U19*W19 -> 0 | Y19: 0 | Z19: 0 | AA19: 4.5 | AB19: 0 | AC19: 8 | AD19: 1 | AE19: 0 | AF19: 0 | AG19: 0 | AH19: 0 | AI19: 0 | AJ19: 0 | AK19: =IF(AI19>0,AI19,AK18) -> 0 | AL19: =IF(AJ19>0,AJ19,AL18) -> 0 | AM19: =AL19*AK19 -> 0 | AN19: =IFERROR(AVERAGEIF(AO12:AO18,">0",AO12:AO18),0) -> 0 | AO19: =AP19*0.75+AQ19*0.125+AR19*0.125 -> 0 | AP19: =AVERAGE(AS19:AT19) -> 0 | AQ19: =AY19/AQ$5 -> 0 | AR19: =IF(AZ19>=0,1/(AZ19+1),0) -> 0 | AS19: =IF((("24:00"-AX19+AU19)/$AS$5)>0,(("24:00"-AX19+AU19)/$AS$5),AS18) -> 0 | AT19: =IF(((AW19-AV19)/$AT$5)>0,((AW19-AV19)/$AT$5),AT18) -> 0 | AU19: 0 | AV19: 0 | AW19: 0 | AX19: 1 | AY19: 0 | AZ19: -1
A20: 45345 | B20: =B$2-A20+1 -> 671 | C20: =D20-B20 -> 4082 | D20: =IF(F20>0,ROUND(((1-G20)/F20),0),FACT(128)) -> 4753 | E20: =F20-F19 -> -1.0590866e-07 | F20: =G20/(ROW()-7) -> 0.00020980152 | G20: =(SUM($I$8:$I20)*(MAX(M$3-M$4,0))+(N20*MAX(M$4,0)))*(1-$AM$4)+(AM20*$AM$4) -> 0.0027274198 | H20: =0.5+(MONTH(A20)+(YEAR(A20)-2024)*12)/((YEAR(B$2)-2023)*12) -> 0.58333333 | I20: =L20*H20 -> 0.0011121633 | J20: =F20*B20+G20 -> 0.14350424 | K20: =((1-G20)/B20)-F20 -> 0.0012764467 | L20: =Y20*Y$6+X20*X$6+Z20*Z$6+AA20*AA$6+AB20*AB$6+AC20*AC$6+AD20*AD$6+AE20*AE$6+AF20*AF$6+AG20*AG$6+AH20*AH$6 -> 0.0019065657 | M20: 0 | N20: =IF(M20>N19,M20,N19) -> 0 | O20: 0 | P20: 0 | Q20: =($P$2-$P$4)+((P20/(MAX(1/FACT(128),O20)))*$P$4) -> 1 | R20: 0 | S20: =O20*$R$5/MAX(1/FACT(128),R20) -> 0 | T20: 0 | U20: =MAX(1,T20)/(MAX(1,O20)) -> 1 | V20: 0 | W20: =($V$4*V20/(MAX(1,O20)))+1 -> 1 | X20: =O20*Q20*S20*U20*W20 -> 0 | Y20: 0 | Z20: 0 | AA20: 2 | AB20: 0 | AC20: 11 | AD20: 3 | AE20: 0 | AF20: 0 | AG20: 0 | AH20: 0 | AI20: 0 | AJ20: 0 | AK20: =IF(AI20>0,AI20,AK19) -> 0 | AL20: =IF(AJ20>0,AJ20,AL19) -> 0 | AM20: =AL20*AK20 -> 0 | AN20: =IFERROR(AVERAGEIF(AO13:AO19,">0",AO13:AO19),0) -> 0 | AO20: =AP20*0.75+AQ20*0.125+AR20*0.125 -> 0 | AP20: =AVERAGE(AS20:AT20) -> 0 | AQ20: =AY20/AQ$5 -> 0 | AR20: =IF(AZ20>=0,1/(AZ20+1),0) -> 0 | AS20: =IF((("24:00"-AX20+AU20)/$AS$5)>0,(("24:00"-AX20+AU20)/$AS$5),AS19) -> 0 | AT20: =IF(((AW20-AV20)/$AT$5)>0,((AW20-AV20)/$AT$5),AT19) -> 0 | AU20: 0 | AV20: 0 | AW20: 0 | AX20: 1 | AY20: 0 | AZ20: -1
A21: 45346 | B21: =B$2-A21+1 -> 670 | C21: =D21-B21 -> 4091 | D21: =IF(F21>0,ROUND(((1-G21)/F21),0),FACT(128)) -> 4761 | E21: =F21-F20 -> -3.8670689e-07 | F21: =G21/(ROW()-7) -> 0.00020941482 | G21: =(SUM($I$8:$I21)*(MAX(M$3-M$4,0))+(N21*MAX(M$4,0)))*(1-$AM$4)+(AM21*$AM$4) -> 0.0029318074 | H21: =0.5+(MONTH(A21)+(YEAR(A21)-2024)*12)/((YEAR(B$2)-2023)*12) -> 0.58333333 | I21: =L21*H21 -> 0.0010900673 | J21: =F21*B21+G21 -> 0.14323973 | K21: =((1-G21)/B21)-F21 -> 0.0012787467 | L21: =Y21*Y$6+X21*X$6+Z21*Z$6+AA21*AA$6+AB21*AB$6+AC21*AC$6+AD21*AD$6+AE21*AE$6+AF21*AF$6+AG21*AG$6+AH21*AH$6 -> 0.0018686869 | M21: 0 | N21: =IF(M21>N20,M21,N20) -> 0 | O21: 0 | P21: 0 | Q21: =($P$2-$P$4)+((P21/(MAX(1/FACT(128),O21)))*$P$4) -> 1 | R21: 0 | S21: =O21*$R$5/MAX(1/FACT(128),R21) -> 0 | T21: 0 | U21: =MAX(1,T21)/(MAX(1,O21)) -> 1 | V21: 0 | W21: =($V$4*V21/(MAX(1,O21)))+1 -> 1 | X21: =O21*Q21*S21*U21*W21 -> 0 | Y21: 0 | Z21: 0 | AA21: 7 | AB21: 0 | AC21: 4 | AD21: 0 | AE21: 0 | AF21: 0 | AG21: 0 | AH21: 0 | AI21: 0 | AJ21: 0 | AK21: =IF(AI21>0,AI21,AK20) -> 0 | AL21: =IF(AJ21>0,AJ21,AL20) -> 0 | AM21: =AL21*AK21 -> 0 | AN21: =IFERROR(AVERAGEIF(AO14:AO20,">0",AO14:AO20),0) -> 0 | AO21: =AP21*0.75+AQ21*0.125+AR21*0.125 -> 0 | AP21: =AVERAGE(AS21:AT21) -> 0 | AQ21: =AY21/AQ$5 -> 0 | AR21: =IF(AZ21>=0,1/(AZ21+1),0) -> 0 | AS21: =IF((("24:00"-AX21+AU21)/$AS$5)>0,(("24:00"-AX21+AU21)/$AS$5),AS20) -> 0 | AT21: =IF(((AW21-AV21)/$AT$5)>0,((AW21-AV21)/$AT$5),AT20) -> 0 | AU21: 0 | AV21: 0 | AW21: 0 | AX21: 1 | AY21: 0 | AZ21: -1
A22: 45347 | B22: =B$2-A22+1 -> 669 | C22: =D22-B22 -> 4094 | D22: =IF(F22>0,ROUND(((1-G22)/F22),0),FACT(128)) -> 4763 | E22: =F22-F21 -> -1.1418637e-07 | F22: =G22/(ROW()-7) -> 0.00020930063 | G22: =(SUM($I$8:$I22)*(MAX(M$3-M$4,0))+(N22*MAX(M$4,0)))*(1-$AM$4)+(AM22*$AM$4) -> 0.0031395094 | H22: =0.5+(MONTH(A22)+(YEAR(A22)-2024)*12)/((YEAR(B$2)-2023)*12) -> 0.58333333 | I22: =L22*H22 -> 0.0011077441 | J22: =F22*B22+G22 -> 0.14316163 | K22: =((1-G22)/B22)-F22 -> 0.0012807748 | L22: =Y22*Y$6+X22*X$6+Z22*Z$6+AA22*AA$6+AB22*AB$6+AC22*AC$6+AD22*AD$6+AE22*AE$6+AF22*AF$6+AG22*AG$6+AH22*AH$6 -> 0.0018989899 | M22: 0 | N22: =IF(M22>N21,M22,N21) -> 0 | O22: 0 | P22: 0 | Q22: =($P$2-$P$4)+((P22/(MAX(1/FACT(128),O22)))*$P$4) -> 1 | R22: 0 | S22: =O22*$R$5/MAX(1/FACT(128),R22) -> 0 | T22: 0 | U22: =MAX(1,T22)/(MAX(1,O22)) -> 1 | V22: 0 | W22: =($V$4*V22/(MAX(1,O22)))+1 -> 1 | X22: =O22*Q22*S22*U22*W22 -> 0 | Y22: 2.08 | Z22: 0 | AA22: 2 | AB22: 0 | AC22: 4 | AD22: 3 | AE22: 0 | AF22: 0 | AG22: 0 | AH22: 0 | AI22: 0 | AJ22: 0 | AK22: =IF(AI22>0,AI22,AK21) -> 0 | AL22: =IF(AJ22>0,AJ22,AL21) -> 0 | AM22: =AL22*AK22 -> 0 | AN22: =IFERROR(AVERAGEIF(AO15:AO21,">0",AO15:AO21),0) -> 0 | AO22: =AP22*0.75+AQ22*0.125+AR22*0.125 -> 0 | AP22: =AVERAGE(AS22:AT22) -> 0 | AQ22: =AY22/AQ$5 -> 0 | AR22: =IF(AZ22>=0,1/(AZ22+1),0) -> 0 | AS22: =IF((("24:00"-AX22+AU22)/$AS$5)>0,(("24:00"-AX22+AU22)/$AS$5),AS21) -> 0 | AT22: =IF(((AW22-AV22)/$AT$5)>0,((AW22-AV22)/$AT$5),AT21) -> 0 | AU22: 0 | AV22: 0 | AW22: 0 | AX22: 1 | AY22: 0 | AZ22: -1
A23: 45348 | B23: =B$2-A23+1 -> 668 | C23: =D23-B23 -> 3996 | D23: =IF(F23>0,ROUND(((1-G23)/F23),0),FACT(128)) -> 4664 | E23: =F23-F22 -> 4.3538038e-06 | F23: =G23/(ROW()-7) -> 0.00021365443 | G23: =(SUM($I$8:$I23)*(MAX(M$3-M$4,0))+(N23*MAX(M$4,0)))*(1-$AM$4)+(AM23*$AM$4) -> 0.0034184709 | H23: =0.5+(MONTH(A23)+(YEAR(A23)-2024)*12)/((YEAR(B$2)-2023)*12) -> 0.58333333 | I23: =L23*H23 -> 0.0014877946 | J23: =F23*B23+G23 -> 0.14613963 | K23: =((1-G23)/B23)-F23 -> 0.0012782341 | L23: =Y23*Y$6+X23*X$6+Z23*Z$6+AA23*AA$6+AB23*AB$6+AC23*AC$6+AD23*AD$6+AE23*AE$6+AF23*AF$6+AG23*AG$6+AH23*AH$6 -> 0.0025505051 | M23: 0 | N23: =IF(M23>N22,M23,N22) -> 0 | O23: 0 | P23: 0 | Q23: =($P$2-$P$4)+((P23/(MAX(1/FACT(128),O23)))*$P$4) -> 1 | R23: 0 | S23: =O23*$R$5/MAX(1/FACT(128),R23) -> 0 | T23: 0 | U23: =MAX(1,T23)/(MAX(1,O23)) -> 1 | V23: 0 | W23: =($V$4*V23/(MAX(1,O23)))+1 -> 1 | X23: =O23*Q23*S23*U23*W23 -> 0 | Y23: 0 | Z23: 0 | AA23: 2 | AB23: 0 | AC23: 10 | AD23: 12 | AE23: 0 | AF23: 0 | AG23: 0 | AH23: 0 | AI23: 0 | AJ23: 0 | AK23: =IF(AI23>0,AI23,AK22) -> 0 | AL23: =IF(AJ23>0,AJ23,AL22) -> 0 | AM23: =AL23*AK23 -> 0 | AN23: =IFERROR(AVERAGEIF(AO16:AO22,">0",AO16:AO22),0) -> 0 | AO23: =AP23*0.75+AQ23*0.125+AR23*0.125 -> 0 | AP23: =AVERAGE(AS23:AT23) -> 0 | AQ23: =AY23/AQ$5 -> 0 | AR23: =IF(AZ23>=0,1/(AZ23+1),0) -> 0 | AS23: =IF((("24:00"-AX23+AU23)/$AS$5)>0,(("24:00"-AX23+AU23)/$AS$5),AS22) -> 0 | AT23: =IF(((AW23-AV23)/$AT$5)>0,((AW23-AV23)/$AT$5),AT22) -> 0 | AU23: 0 | AV23: 0 | AW23: 0 | AX23: 1 | AY23: 0 | AZ23: -1
A24: 45349 | B24: =B$2-A24+1 -> 667 | C24: =D24-B24 -> 4000 | D24: =IF(F24>0,ROUND(((1-G24)/F24),0),FACT(128)) -> 4667 | E24: =F24-F23 -> -1.3893056e-07 | F24: =G24/(ROW()-7) -> 0.0002135155 | G24: =(SUM($I$8:$I24)*(MAX(M$3-M$4,0))+(N24*MAX(M$4,0)))*(1-$AM$4)+(AM24*$AM$4) -> 0.0036297635 | H24: =0.5+(MONTH(A24)+(YEAR(A24)-2024)*12)/((YEAR(B$2)-2023)*12) -> 0.58333333 | I24: =L24*H24 -> 0.0011268939 | J24: =F24*B24+G24 -> 0.1460446 | K24: =((1-G24)/B24)-F24 -> 0.0012802929 | L24: =Y24*Y$6+X24*X$6+Z24*Z$6+AA24*AA$6+AB24*AB$6+AC24*AC$6+AD24*AD$6+AE24*AE$6+AF24*AF$6+AG24*AG$6+AH24*AH$6 -> 0.0019318182 | M24: 0 | N24: =IF(M24>N23,M24,N23) -> 0 | O24: 0 | P24: 0 | Q24: =($P$2-$P$4)+((P24/(MAX(1/FACT(128),O24)))*$P$4) -> 1 | R24: 0 | S24: =O24*$R$5/MAX(1/FACT(128),R24) -> 0 | T24: 0 | U24: =MAX(1,T24)/(MAX(1,O24)) -> 1 | V24: 0 | W24: =($V$4*V24/(MAX(1,O24)))+1 -> 1 | X24: =O24*Q24*S24*U24*W24 -> 0 | Y24: 0 | Z24: 0 | AA24: 6 | AB24: 1 | AC24: 5 | AD24: 0 | AE24: 0 | AF24: 0 | AG24: 0 | AH24: 0 | AI24: 0 | AJ24: 0 | AK24: =IF(AI24>0,AI24,AK23) -> 0 | AL24: =IF(AJ24>0,AJ24,AL23) -> 0 | AM24: =AL24*AK24 -> 0 | AN24: =IFERROR(AVERAGEIF(AO17:AO23,">0",AO17:AO23),0) -> 0 | AO24: =AP24*0.75+AQ24*0.125+AR24*0.125 -> 0 | AP24: =AVERAGE(AS24:AT24) -> 0 | AQ24: =AY24/AQ$5 -> 0 | AR24: =IF(AZ24>=0,1/(AZ24+1),0) -> 0 | AS24: =IF((("24:00"-AX24+AU24)/$AS$5)>0,(("24:00"-AX24+AU24)/$AS$5),AS23) -> 0 | AT24: =IF(((AW24-AV24)/$AT$5)>0,((AW24-AV24)/$AT$5),AT23) -> 0 | AU24: 0 | AV24: 0 | AW24: 0 | AX24: 1 | AY24: 0 | AZ24: -1
A25: 45350 | B25: =B$2-A25+1 -> 666 | C25: =D25-B25 -> 4004 | D25: =IF(F25>0,ROUND(((1-G25)/F25),0),FACT(128)) -> 4670 | E25: =F25-F24 -> -2.0021591e-07 | F25: =G25/(ROW()-7) -> 0.00021331529 | G25: =(SUM($I$8:$I25)*(MAX(M$3-M$4,0))+(N25*MAX(M$4,0)))*(1-$AM$4)+(AM25*$AM$4) -> 0.0038396752 | H25: =0.5+(MONTH(A25)+(YEAR(A25)-2024)*12)/((YEAR(B$2)-2023)*12) -> 0.58333333 | I25: =L25*H25 -> 0.0011195286 | J25: =F25*B25+G25 -> 0.14590766 | K25: =((1-G25)/B25)-F25 -> 0.0012824209 | L25: =Y25*Y$6+X25*X$6+Z25*Z$6+AA25*AA$6+AB25*AB$6+AC25*AC$6+AD25*AD$6+AE25*AE$6+AF25*AF$6+AG25*AG$6+AH25*AH$6 -> 0.0019191919 | M25: 0 | N25: =IF(M25>N24,M25,N24) -> 0 | O25: 0 | P25: 0 | Q25: =($P$2-$P$4)+((P25/(MAX(1/FACT(128),O25)))*$P$4) -> 1 | R25: 0 | S25: =O25*$R$5/MAX(1/FACT(128),R25) -> 0 | T25: 0 | U25: =MAX(1,T25)/(MAX(1,O25)) -> 1 | V25: 0 | W25: =($V$4*V25/(MAX(1,O25)))+1 -> 1 | X25: =O25*Q25*S25*U25*W25 -> 0 | Y25: 0 | Z25: 0 | AA25: 5 | AB25: 0 | AC25: 8 | AD25: 0 | AE25: 0 | AF25: 0 | AG25: 0 | AH25: 0 | AI25: 0 | AJ25: 0 | AK25: =IF(AI25>0,AI25,AK24) -> 0 | AL25: =IF(AJ25>0,AJ25,AL24) -> 0 | AM25: =AL25*AK25 -> 0 | AN25: =IFERROR(AVERAGEIF(AO18:AO24,">0",AO18:AO24),0) -> 0 | AO25: =AP25*0.75+AQ25*0.125+AR25*0.125 -> 0 | AP25: =AVERAGE(AS25:AT25) -> 0 | AQ25: =AY25/AQ$5 -> 0 | AR25: =IF(AZ25>=0,1/(AZ25+1),0) -> 0 | AS25: =IF((("24:00"-AX25+AU25)/$AS$5)>0,(("24:00"-AX25+AU25)/$AS$5),AS24) -> 0 | AT25: =IF(((AW25-AV25)/$AT$5)>0,((AW25-AV25)/$AT$5),AT24) -> 0 | AU25: 0 | AV25: 0 | AW25: 0 | AX25: 1 | AY25: 0 | AZ25: -1
A26: 45351 | B26: =B$2-A26+1 -> 665 | C26: =D26-B26 -> 4007 | D26: =IF(F26>0,ROUND(((1-G26)/F26),0),FACT(128)) -> 4672 | E26: =F26-F25 -> -1.4279852e-07 | F26: =G26/(ROW()-7) -> 0.00021317249 | G26: =(SUM($I$8:$I26)*(MAX(M$3-M$4,0))+(N26*MAX(M$4,0)))*(1-$AM$4)+(AM26*$AM$4) -> 0.0040502773 | H26: =0.5+(MONTH(A26)+(YEAR(A26)-2024)*12)/((YEAR(B$2)-2023)*12) -> 0.58333333 | I26: =L26*H26 -> 0.0011232113 | J26: =F26*B26+G26 -> 0.14580998 | K26: =((1-G26)/B26)-F26 -> 0.0012844963 | L26: =Y26*Y$6+X26*X$6+Z26*Z$6+AA26*AA$6+AB26*AB$6+AC26*AC$6+AD26*AD$6+AE26*AE$6+AF26*AF$6+AG26*AG$6+AH26*AH$6 -> 0.0019255051 | M26: 0 | N26: =IF(M26>N25,M26,N25) -> 0 | O26: 0 | P26: 0 | Q26: =($P$2-$P$4)+((P26/(MAX(1/FACT(128),O26)))*$P$4) -> 1 | R26: 0 | S26: =O26*$R$5/MAX(1/FACT(128),R26) -> 0 | T26: 0 | U26: =MAX(1,T26)/(MAX(1,O26)) -> 1 | V26: 0 | W26: =($V$4*V26/(MAX(1,O26)))+1 -> 1 | X26: =O26*Q26*S26*U26*W26 -> 0 | Y26: 4.25 | Z26: 0 | AA26: 1 | AB26: 0 | AC26: 1 | AD26: 0 | AE26: 0 | AF26: 0 | AG26: 0 | AH26: 0 | AI26: 0 | AJ26: 0 | AK26: =IF(AI26>0,AI26,AK25) -> 0 | AL26: =IF(AJ26>0,AJ26,AL25) -> 0 | AM26: =AL26*AK26 -> 0 | AN26: =IFERROR(AVERAGEIF(AO19:AO25,">0",AO19:AO25),0) -> 0 | AO26: =AP26*0.75+AQ26*0.125+AR26*0.125 -> 0 | AP26: =AVERAGE(AS26:AT26) -> 0 | AQ26: =AY26/AQ$5 -> 0 | AR26: =IF(AZ26>=0,1/(AZ26+1),0) -> 0 | AS26: =IF((("24:00"-AX26+AU26)/$AS$5)>0,(("24:00"-AX26+AU26)/$AS$5),AS25) -> 0 | AT26: =IF(((AW26-AV26)/$AT$5)>0,((AW26-AV26)/$AT$5),AT25) -> 0 | AU26: 0 | AV26: 0 | AW26: 0 | AX26: 1 | AY26: 0 | AZ26: -1
... A690: 46015 | B690: =B$2-A690+1 -> 1 | C690: =D690-B690 -> -23 | D690: =IF(F690>0,ROUND(((1-G690)/F690),0),FACT(128)) -> -22 | E690: =F690-F689 -> -2.2177842e-06 | F690: =G690/(ROW()-7) -> 0.0015125288 | G690: =(SUM($I$8:$I690)*(MAX(M$3-M$4,0))+(N690*MAX(M$4,0)))*(1-$AM$4)+(AM690*$AM$4) -> 1.0330572 | H690: =0.5+(MONTH(A690)+(YEAR(A690)-2024)*12)/((YEAR(B$2)-2023)*12) -> 1.5 | I690: =L690*H690 -> 0 | J690: =F690*B690+G690 -> 1.0345697 | K690: =((1-G690)/B690)-F690 -> -0.034569722 | L690: =Y690*Y$6+X690*X$6+Z690*Z$6+AA690*AA$6+AB690*AB$6+AC690*AC$6+AD690*AD$6+AE690*AE$6+AF690*AF$6+AG690*AG$6+AH690*AH$6 -> 0 | M690: 0 | N690: =IF(M690>N689,M690,N689) -> 1 | O690: 0 | P690: 0 | Q690: =($P$2-$P$4)+((P690/(MAX(1/FACT(128),O690)))*$P$4) -> 1 | R690: 0 | S690: =O690*$R$5/MAX(1/FACT(128),R690) -> 0 | T690: 0 | U690: =MAX(1,T690)/(MAX(1,O690)) -> 1 | V690: 0 | W690: =($V$4*V690/(MAX(1,O690)))+1 -> 1 | X690: =O690*Q690*S690*U690*W690 -> 0 | Y690: 0 | Z690: 0 | AA690: 0 | AB690: 0 | AC690: 0 | AD690: 0 | AE690: 0 | AF690: 0 | AG690: 0 | AH690: 0 | AI690: 0 | AJ690: 0 | AK690: =IF(AI690>0,AI690,AK689) -> 0.3611 | AL690: =IF(AJ690>0,AJ690,AL689) -> 0.0034809524 | AM690: =AL690*AK690 -> 0.0012569719 | AN690: =IFERROR(AVERAGEIF(AO683:AO689,">0",AO683:AO689),0) -> 0.7921875 | AO690: =AP690*0.75+AQ690*0.125+AR690*0.125 -> 0.7921875 | AP690: =AVERAGE(AS690:AT690) -> 1.05625 | AQ690: =AY690/AQ$5 -> 0 | AR690: =IF(AZ690>=0,1/(AZ690+1),0) -> 0 | AS690: =IF((("24:00"-AX690+AU690)/$AS$5)>0,(("24:00"-AX690+AU690)/$AS$5),AS689) -> 1.0791667 | AT690: =IF(((AW690-AV690)/$AT$5)>0,((AW690-AV690)/$AT$5),AT689) -> 1.0333333 | AU690: 0 | AV690: 0 | AW690: 0 | AX690: 1 | AY690: 0 | AZ690: -1

Sheet Sheet2
A1: 机构 | B1: 金榜时代 | F1: 新东方 | K1: 笔记做题 | L1: 20251109 | M1: 20251122 | N1: 20251126
A2: 书名 | B2: 讲义 | C2: 660题 | D2: 易错题 | E2: 严选题 | F2: 讲义 | G2: 2021习题 | H2: 2022习题 | I2: 真题 | P2: x=Cy
A3: 页数 | B3: 187 | C3: 144 | D3: 57 | E3: 44 | F3: 196 | G3: 59 | H3: 67 | I3: 155 | K3: 算1题 | L3: 特征值 | M3: 特征向量 | N3: 齐次通解 | O3: 非齐次特解 | P3: 求出C逆 | Q3: 求出C
A4: 目前 | B4: 187 | C4: 144 | D4: 57 | E4: 44 | F4: 196 | G4: 59 | H4: 67 | I4: 155
A5: 进度 | B5: =B4/MAX(1,B3) -> 1 | C5: =C4/MAX(1,C3) -> 1 | D5: =D4/MAX(1,D3) -> 1 | E5: =E4/MAX(1,E3) -> 1 | F5: =F4/MAX(1,F3) -> 1 | G5: =G4/MAX(1,G3) -> 1 | H5: =H4/MAX(1,H3) -> 1 | I5: =I4/MAX(1,I3) -> 1
A6: 平均 | B6: =AVERAGE(B5:I5) -> 1
A8: 年份 | B8: 专业选择 | C8: 专业大题 | D8: 数学选择 | E8: 数学填空 | F8: 数学大题 | G8: 专业总分 | H8: 数学总分 | I8: 专选比值 | J8: 专大比值 | K8: 数选比值 | L8: 数填比值 | M8: 数大比值 | N8: 专总比值 | O8: 数总比值
A9: 2021
A10: 2022
A11: 2023
A12: 2024
A13: 2025
A14: 总分值 | B14: 80 | C14: 70 | D14: 50 | E14: 30 | F14: 70 | G14: 150 | H14: 150 | I14: 1 | J14: 1 | K14: 1 | L14: 1 | M14: 1 | N14: 1 | O14: 1
A16: 卷名 | B16: 徐涛 | C16: 肖八 | D16: 徐涛 | E16: 肖八 | F16: 徐涛 | G16: 肖八 | H16: 徐涛 | I16: 徐涛 | J16: 肖八 | K16: 肖八 | L16: 肖国内事 | M16: 肖国内事 | N16: 肖国内事 | O16: 肖国内事 | P16: 肖国内事 | Q16: 肖国内事 | R16: 肖国内事 | S16: 肖国外事 | T16: 肖国外事 | U16: 肖国外事 | V16: 肖八 | W16: 肖八 | X16: 肖八 | Y16: 肖4 | Z16: 肖4 | AA16: 肖4 | AB16: 肖4
A17: 卷号 | B17: 1 | C17: 1 | D17: 2 | E17: 2 | F17: 3 | G17: 3 | H17: 4 | I17: 5 | J17: 4 | K17: 5 | L17: (1/7) | M17: (2/7) | N17: (3/7) | O17: (4/7) | P17: (5/7) | Q17: (6/7) | R17: (7/7) | S17: (1/3) | T17: (1/3) | U17: (1/3) | V17: 6 | W17: 7 | X17: 8 | Y17: 1 | Z17: 2 | AA17: 3 | AB17: 4
A18: 20251118 | B18: 20
A19: 20251119 | B19: 13 | C19: 33 | D19: 33 | E19: 20
A20: 20251120 | E20: 13 | F20: 33 | G20: 33 | H20: 33 | I20: 33
A21: 20251121 | J21: 33
A22: 20251122 | K22: 33
A23: 20251123 | L23: 33
A24: 20251124 | M24: 33
A25: 20251125 | N25: 33
A26: 20251126 | O26: 33 | P26: 33
A27: 20251127 | Q27: 33 | R27: 3 | S27: 33
A28: 20251128 | T28: 33 | U28: 7
A29: 20251129 | V29: 33 | W29: 33 | X29: 33
A30: 20251130
A31: 20251201
A32: 20251202
A33: 20251203
A34: 20251204
A35: 20251205
A36: 20251206
A37: 20251207
A38: 20251208
A39: 20251209 | Y39: 33
A40: 20251210 | Z40: 33 | AA40: 33
A41: 20251211 | AB41: 33
A42: 20251212
...

Sheet Sheet3
A1: 平均 | B1: 马原 | C1: 毛概 | D1: 近代 | E1: 思修 | F1: 新时 | G1: 综合 | H1: 时政
A2: =AVERAGE(B2:H2) -> 0.0034809524 | B2: =AVERAGEIF(B3:B9,"<>NA")*0.01 -> 0.016733333 | C2: =AVERAGEIF(C3:C9,"<>NA")*0.01 -> 0.0049333333 | D2: =AVERAGEIF(D3:D9,"<>NA")*0.01 -> 0 | E2: =AVERAGEIF(E3:E9,"<>NA")*0.01 -> 0 | F2: =AVERAGEIF(F3:F9,"<>NA")*0.01 -> 0 | G2: =AVERAGEIF(G3:G9,"<>NA")*0.01 -> 0.0027 | H2: =AVERAGEIF(H3:H9,"<>NA")*0.01 -> 0
A3: 1600 | B3: 5.02 | C3: 0.38 | D3: 0 | E3: 0 | F3: NA | G3: NA | H3: NA
A4: 600 | B4: 0 | C4: 1.1 | D4: 0 | E4: 0 | F4: 0 | G4: NA | H4: NA
A5: 真题 | B5: NA | C5: NA | D5: NA | E5: NA | F5: NA | G5: 0.81 | H5: NA
A6: 真题（章节） | B6: 0 | C6: 0 | D6: 0 | E6: 0 | F6: NA | G6: NA | H6: NA
A7: 冲刺300 | B7: NA | C7: NA | D7: NA | E7: NA | F7: NA | G7: 0 | H7: NA
A8: 每日 | B8: NA | C8: NA | D8: NA | E8: NA | F8: NA | G8: 0 | H8: NA
A9: 时政 | B9: NA | C9: NA | D9: NA | E9: NA | F9: NA | G9: NA | H9: 0
A11: 笔记复习 | B11: 总计
A12: 20251125 | B12: =SUM(C12:AA12) -> 10 | C12: 0 | D12: 3.5 | E12: 0.5 | F12: 1 | G12: 5
A13: 20251126 | B13: =SUM(C13:AA13) -> 10 | C13: 0.5 | D13: 0.5 | E13: 3 | F13: 2 | G13: 1.5 | H13: 1 | I13: 1.5
A14: =B13+B14 -> 20.5 | B14: =SUM(C14:AA14) -> 10.5 | C14: 0.5 | D14: 1 | E14: 0.5 | F14: 0.5 | G14: 1 | H14: 0.5 | I14: 2 | J14: 3 | K14: 0.5 | L14: 1
A15: 20251201 | B15: =SUM(C15:AA15) -> 21 | C15: 3 | D15: 4 | E15: 4 | F15: 1 | G15: 4.5 | H15: 2 | I15: 2.5
A16: =B15+B16 -> 34 | B16: =SUM(C16:AA16) -> 13 | C16: 2 | D16: 1 | E16: 0.5 | F16: 1 | G16: 1.5 | H16: 1 | I16: 1 | J16: 0.5 | K16: 0.5 | L16: 0.5 | M16: 0.5 | N16: 3
A17: =A16+B17 -> 41 | B17: =SUM(C17:AA17) -> 7 | C17: 2 | D17: 2 | E17: 3
A18: 20251202 | B18: =SUM(C18:AA18) -> 22 | C18: 6 | D18: 1 | E18: 1 | F18: 0.5 | G18: 2 | H18: 2.5 | I18: 3 | J18: 3 | K18: 3
A19: =B18+B19 -> 46 | B19: =SUM(C19:AA19) -> 24 | C19: 4.5 | D19: 0.5 | E19: 2 | F19: 5.5 | G19: 2.5 | H19: 1.5 | I19: 7.5
A20: 20251203 | B20: =SUM(C20:AA20) -> 21.5 | C20: 3 | D20: 1.5 | E20: 3 | F20: 3.5 | G20: 3.5 | H20: 3 | I20: 4
A21: =B20+B21 -> 34 | B21: =SUM(C21:AA21) -> 12.5 | C21: 3 | D21: 4 | E21: 3.5 | F21: 2
A22: 20251204 | B22: =SUM(C22:AA22) -> 20 | C22: 1.5 | D22: 2.5 | E22: 1.5 | F22: 3.5 | G22: 6 | H22: 3 | I22: 2
A23: 20251205 | B23: =SUM(C23:AA23) -> 23 | C23: 7 | D23: 6 | E23: 0.5 | F23: 1 | G23: 1 | H23: 1 | I23: 3 | J23: 3.5
A24: 20251206 | B24: =SUM(C24:AA24) -> 12.5 | C24: 3.5 | D24: 2.5 | E24: 1.5 | F24: 0.5 | G24: 1 | H24: 0.5 | I24: 0.5 | J24: 0.5 | K24: 0.5 | L24: 0.5 | M24: 0.5 | N24: 0.5
A25: =B24+B25 -> 20 | B25: =SUM(C25:AA25) -> 7.5 | C25: 1.5 | D25: 0.5 | E25: 0.5 | F25: 5
A26: 20251207 | B26: =SUM(C26:AA26) -> 11 | C26: 1.5 | D26: 0.5 | E26: 6.5 | F26: 0.5 | G26: 0.5 | H26: 0.5 | I26: 0.5 | J26: 0.5
A27: =B26+B27 -> 18 | B27: =SUM(C27:AA27) -> 7 | C27: 0.5 | D27: 0.5 | E27: 0.5 | F27: 1.5 | G27: 1.5 | H27: 2.5
A28: =A27+B28 -> 24 | B28: =SUM(C28:AA28) -> 6 | C28: 0.5 | D28: 1 | E28: 1 | F28: 0.5 | G28: 1.5 | H28: 0.5 | I28: 1
A29: 20251208 | B29: =SUM(C29:AA29) -> 13 | C29: 1.5 | D29: 0.5 | E29: 3 | F29: 8
A30: =B29+B30 -> 38.5 | B30: =SUM(C30:AA30) -> 25.5 | C30: 0.5 | D30: 1 | E30: 0.5 | F30: 10 | G30: 3.5 | H30: 1 | I30: 0.5 | J30: 0.5 | K30: 8
A31: 20251209 | B31: =SUM(C31:AA31) -> 14.5 | C31: 4 | D31: 0.5 | E31: 0.5 | F31: 4 | G31: 4.5 | H31: 0.5 | I31: 0.5
A32: 20251210 | B32: =SUM(C32:AA32) -> 0
A33: 20251211 | B33: =SUM(C33:AA33) -> 0
A34: 20251212 | B34: =SUM(C34:AA34) -> 0
A35: 20251213 | B35: =SUM(C35:AA35) -> 0
A36: 20251214 | B36: =SUM(C36:AA36) -> 0
A37: 20251215 | B37: =SUM(C37:AA37) -> 0
A38: 20251216 | B38: =SUM(C38:AA38) -> 0
A39: 20251217 | B39: =SUM(C39:AA39) -> 0
A40: 20251218 | B40: =SUM(C40:AA40) -> 0
A41: 20251219 | B41: =SUM(C41:AA41) -> 0
...

Sheet Sheet4
A1: =Sheet1!A1 -> 日期 | B1: =Sheet1!L1 -> 每日进度（数理） | C1: =Sheet1!F1 -> 日均进度 | D1: =Sheet1!G1 -> 总进度 | E1: 身体状态 | F1: 目标 | G1: 目标（除政治）
A2: =Sheet1!A8 -> 45333 | B2: =Sheet1!L8 -> 0.001637588 | C2: =Sheet1!F8 -> 0.00017911119 | D2: =Sheet1!G8 -> 0.00017911119 | E2: =Sheet1!AN8*MAX(B$2:B$318)/MAX(Sheet1!AN$8:AN$324) -> 0 | F2: 1 | G2: 0.75
A3: =Sheet1!A9 -> 45334 | B3: =Sheet1!L9 -> 0.0017045455 | C3: =Sheet1!F9 -> 0.00018277292 | D3: =Sheet1!G9 -> 0.00036554585 | E3: =Sheet1!AN9*MAX(B$2:B$318)/MAX(Sheet1!AN$8:AN$324) -> 0 | F3: 1 | G3: 0.75
A4: =Sheet1!A10 -> 45335 | B4: =Sheet1!L10 -> 0.0018055556 | C4: =Sheet1!F10 -> 0.00018767616 | D4: =Sheet1!G10 -> 0.00056302849 | E4: =Sheet1!AN10*MAX(B$2:B$318)/MAX(Sheet1!AN$8:AN$324) -> 0 | F4: 1 | G4: 0.75
A5: =Sheet1!A11 -> 45336 | B5: =Sheet1!L11 -> 0.0017272727 | C5: =Sheet1!F11 -> 0.00018798724 | D5: =Sheet1!G11 -> 0.00075194894 | E5: =Sheet1!AN11*MAX(B$2:B$318)/MAX(Sheet1!AN$8:AN$324) -> 0 | F5: 1 | G5: 0.75
A6: =Sheet1!A12 -> 45337 | B6: =Sheet1!L12 -> 0.0017777778 | C6: =Sheet1!F12 -> 0.00018927868 | D6: =Sheet1!G12 -> 0.00094639338 | E6: =Sheet1!AN12*MAX(B$2:B$318)/MAX(Sheet1!AN$8:AN$324) -> 0 | F6: 1 | G6: 0.75
A7: =Sheet1!A13 -> 45338 | B7: =Sheet1!L13 -> 0.0019065657 | C7: =Sheet1!F13 -> 0.00019248733 | D7: =Sheet1!G13 -> 0.001154924 | E7: =Sheet1!AN13*MAX(B$2:B$318)/MAX(Sheet1!AN$8:AN$324) -> 0 | F7: 1 | G7: 0.75
A8: =Sheet1!A14 -> 45339 | B8: =Sheet1!L14 -> 0.0018686869 | C8: =Sheet1!F14 -> 0.00019418738 | D8: =Sheet1!G14 -> 0.0013593116 | E8: =Sheet1!AN14*MAX(B$2:B$318)/MAX(Sheet1!AN$8:AN$324) -> 0 | F8: 1 | G8: 0.75
A9: =Sheet1!A15 -> 45340 | B9: =Sheet1!L15 -> 0.0020117845 | C9: =Sheet1!F15 -> 0.00019741882 | D9: =Sheet1!G15 -> 0.0015793506 | E9: =Sheet1!AN15*MAX(B$2:B$318)/MAX(Sheet1!AN$8:AN$324) -> 0 | F9: 1 | G9: 0.75
A10: =Sheet1!A16 -> 45341 | B10: =Sheet1!L16 -> 0.0018013468 | C10: =Sheet1!F16 -> 0.00019737476 | D10: =Sheet1!G16 -> 0.0017763729 | E10: =Sheet1!AN16*MAX(B$2:B$318)/MAX(Sheet1!AN$8:AN$324) -> 0 | F10: 1 | G10: 0.75
A11: =Sheet1!A17 -> 45342 | B11: =Sheet1!L17 -> 0.0017676768 | C11: =Sheet1!F17 -> 0.00019697125 | D11: =Sheet1!G17 -> 0.0019697125 | E11: =Sheet1!AN17*MAX(B$2:B$318)/MAX(Sheet1!AN$8:AN$324) -> 0 | F11: 1 | G11: 0.75
A12: =Sheet1!A18 -> 45343 | B12: =Sheet1!L18 -> 0.0031186869 | C12: =Sheet1!F18 -> 0.00021007444 | D12: =Sheet1!G18 -> 0.0023108189 | E12: =Sheet1!AN18*MAX(B$2:B$318)/MAX(Sheet1!AN$8:AN$324) -> 0 | F12: 1 | G12: 0.75
A13: =Sheet1!A19 -> 45344 | B13: =Sheet1!L19 -> 0.0019023569 | C13: =Sheet1!F19 -> 0.00020990743 | D13: =Sheet1!G19 -> 0.0025188892 | E13: =Sheet1!AN19*MAX(B$2:B$318)/MAX(Sheet1!AN$8:AN$324) -> 0 | F13: 1 | G13: 0.75
... A684: =Sheet1!A690 -> 46015 | B684: =Sheet1!L690 -> 0 | C684: =Sheet1!F690 -> 0.0015125288 | D684: =Sheet1!G690 -> 1.0330572 | E684: =Sheet1!AN690*MAX(B$2:B$318)/MAX(Sheet1!AN$8:AN$324) -> 0.016563475 | F684: 1 | G684: 0.75
